Workbook

Sheet Code ONU
A1: Pays ONU | B1: Code ONU | C1: ISO3 Alpha-code | D1: Nom Pays | E1: Region OLF
A2: Afghanistan | B2: 4 | C2: AFG | D2: Afghanistan | E2: Asie
A3: Albania | B3: 8 | C3: ALB | D3: Albanie | E3: Europe centrale et orientale
A4: Algeria | B4: 12 | C4: DZA | D4: Algérie | E4: Afrique du Nord
A5: American Samoa | B5: 16 | C5: ASM | D5: Samoa américaines | E5: Océanie
A6: Andorra | B6: 20 | C6: AND | D6: Andorre | E6: Europe occidentale
A7: Angola | B7: 24 | C7: AGO | D7: Angola | E7: Afrique centrale
A8: Anguilla | B8: 660 | C8: AIA | D8: Anguilla | E8: Caraïbes
A9: Antigua and Barbuda | B9: 28 | C9: ATG | D9: Antigua-et-Barbuda | E9: Caraïbes
A10: Argentina | B10: 32 | C10: ARG | D10: Argentine | E10: Amériques
A11: Armenia | B11: 51 | C11: ARM | D11: Arménie | E11: Moyen-Orient
A12: Aruba | B12: 533 | C12: ABW | D12: Aruba | E12: Caraïbes
A13: Australia | B13: 36 | C13: AUS | D13: Australie | E13: Océanie
... A231: Zimbabwe | B231: 716 | C231: ZWE | D231: Zimbabwe | E231: Afrique de l'Est

Sheet Nombre francophones
A1: Pays | B1: Région | C1: Code ISO | D1: Année | E1: Poulation en milliers | F1: Nombre Francophones en milliers | G1: Pourcentage de Francophones
A2: Albanie | B2: =VLOOKUP(C2,'Code ONU'!$C$1:$E$231,3,FALSE) -> Europe centrale et orientale | C2: ALB | D2: 2025 | E2: 2771.5075 | F2: 28.749 | G2: 0.0104
A3: Algérie | B3: =VLOOKUP(C3,'Code ONU'!$C$1:$E$231,3,FALSE) -> Afrique du Nord | C3: DZA | D3: 2025 | E3: 47435.312 | F3: 15589.056 | G3: 0.3286
A4: Allemagne | B4: =VLOOKUP(C4,'Code ONU'!$C$1:$E$231,3,FALSE) -> Europe occidentale | C4: DEU | D4: 2025 | E4: 84075.075 | F4: 14527.367 | G4: 0.1728
A5: Andorre | B5: =VLOOKUP(C5,'Code ONU'!$C$1:$E$231,3,FALSE) -> Europe occidentale | C5: AND | D5: 2025 | E5: 82.9045 | F5: 58.133 | G5: 0.7012
A6: Arménie | B6: =VLOOKUP(C6,'Code ONU'!$C$1:$E$231,3,FALSE) -> Moyen-Orient | C6: ARM | D6: 2025 | E6: 2952.3645 | F6: 4.724 | G6: 0.0016
A7: Autriche | B7: =VLOOKUP(C7,'Code ONU'!$C$1:$E$231,3,FALSE) -> Europe occidentale | C7: AUT | D7: 2025 | E7: 9113.574 | F7: 916.379 | G7: 0.1006
A8: Belgique | B8: =VLOOKUP(C8,'Code ONU'!$C$1:$E$231,3,FALSE) -> Europe occidentale | C8: BEL | D8: 2025 | E8: 11758.603 | F8: 9061.923 | G8: 0.7707
A9: Bénin | B9: =VLOOKUP(C9,'Code ONU'!$C$1:$E$231,3,FALSE) -> Afrique de l'Ouest | C9: BEN | D9: 2025 | E9: 14814.46 | F9: 4992.009 | G9: 0.337
A10: Bosnie-Herzégovine | B10: =VLOOKUP(C10,'Code ONU'!$C$1:$E$231,3,FALSE) -> Europe centrale et orientale | C10: BIH | D10: 2025 | E10: 3140.0955 | F10: 24.013 | G10: 0.0076
A11: Bulgarie | B11: =VLOOKUP(C11,'Code ONU'!$C$1:$E$231,3,FALSE) -> Europe centrale et orientale | C11: BGR | D11: 2025 | E11: 6714.5595 | F11: 129.709 | G11: 0.0193
A12: Burkina Faso | B12: =VLOOKUP(C12,'Code ONU'!$C$1:$E$231,3,FALSE) -> Afrique de l'Ouest | C12: BFA | D12: 2025 | E12: 24074.58 | F12: 5499.253 | G12: 0.2284
A13: Burundi | B13: =VLOOKUP(C13,'Code ONU'!$C$1:$E$231,3,FALSE) -> Afrique de l'Est | C13: BDI | D13: 2025 | E13: 14390.003 | F13: 1249.675 | G13: 0.0868
... A348: Chypre | B348: =VLOOKUP(C348,'Code ONU'!$C$1:$E$231,3,FALSE) -> Moyen-Orient | C348: CYP | D348: 2018 | E348: 1263 | F348: 83 | G348: 0.065716548
A349: Colombie | B349: =VLOOKUP(C349,'Code ONU'!$C$1:$E$231,3,FALSE) -> Amériques | C349: COL | D349: 2018 | E349: 48560 | G349: 0
A350: Comores | B350: =VLOOKUP(C350,'Code ONU'!$C$1:$E$231,3,FALSE) -> Afrique australe et Océan Indien | C350: COM | D350: 2018 | E350: 764 | F350: 198 | G350: 0.2591623
A351: Congo | B351: =VLOOKUP(C351,'Code ONU'!$C$1:$E$231,3,FALSE) -> Afrique centrale | C351: COG | D351: 2018 | E351: 5416 | F351: 3192 | G351: 0.58936484
A352: Congo (République démocratique du) | B352: =VLOOKUP(C352,'Code ONU'!$C$1:$E$231,3,FALSE) -> Afrique centrale | C352: COD | D352: 2018 | E352: 88613 | F352: 44866 | G352: 0.50631397
A353: Costa Rica | B353: =VLOOKUP(C353,'Code ONU'!$C$1:$E$231,3,FALSE) -> Amériques | C353: CRI | D353: 2018 | E353: 4936 | F353: 5 | G353: 0.001012966
A354: Côte d’Ivoire | B354: =VLOOKUP(C354,'Code ONU'!$C$1:$E$231,3,FALSE) -> Afrique de l'Ouest | C354: CIV | D354: 2018 | E354: 27100 | F354: 8987 | G354: 0.33162362
A355: Croatie | B355: =VLOOKUP(C355,'Code ONU'!$C$1:$E$231,3,FALSE) -> Europe centrale et orientale | C355: HRV | D355: 2018 | E355: 4047 | F355: 95 | G355: 0.023474178
A356: Danemark | B356: =VLOOKUP(C356,'Code ONU'!$C$1:$E$231,3,FALSE) -> Europe occidentale | C356: DNK | D356: 2018 | E356: 5781 | F356: 434 | G356: 0.075073517
A357: Djibouti | B357: =VLOOKUP(C357,'Code ONU'!$C$1:$E$231,3,FALSE) -> Afrique de l'Est | C357: DJI | D357: 2018 | E357: 1063 | F357: 532 | G357: 0.50047037
A358: Dominique | B358: =VLOOKUP(C358,'Code ONU'!$C$1:$E$231,3,FALSE) -> Caraïbes | C358: DMA | D358: 2018 | E358: 68 | F358: 7 | G358: 0.10294118
A359: Égypte | B359: =VLOOKUP(C359,'Code ONU'!$C$1:$E$231,3,FALSE) -> Afrique du Nord | C359: EGY | D359: 2018 | E359: 104717 | F359: 3161 | G359: 0.030186121
A360: Émirats arabes unis | B360: =VLOOKUP(C360,'Code ONU'!$C$1:$E$231,3,FALSE) -> Moyen-Orient | C360: ARE | D360: 2018 | E360: 9296 | F360: 244 | G360: 0.026247849
A361: Espagne | B361: =VLOOKUP(C361,'Code ONU'!$C$1:$E$231,3,FALSE) -> Europe occidentale | C361: ESP | D361: 2018 | E361: 46952 | F361: 5509 | G361: 0.11733259
... A367: Gabon | B367: =VLOOKUP(C367,'Code ONU'!$C$1:$E$231,3,FALSE) -> Afrique centrale | C367: GAB | D367: 2018 | E367: 2185 | F367: 1445 | G367: 0.66132723
A368: Gambie | B368: =VLOOKUP(C368,'Code ONU'!$C$1:$E$231,3,FALSE) -> Afrique de l'Ouest | C368: GMB | D368: 2018 | E368: 2371 | G368: 0
A369: Géorgie | B369: =VLOOKUP(C369,'Code ONU'!$C$1:$E$231,3,FALSE) -> Moyen-Orient | C369: GEO | D369: 2018 | E369: 3793 | F369: 16 | G369: 0.0042182969
A370: Ghana | B370: =VLOOKUP(C370,'Code ONU'!$C$1:$E$231,3,FALSE) -> Afrique de l'Ouest | C370: GHA | D370: 2018 | E370: 30327 | F370: 251 | G370: 0.0082764533
A371: Grèce | B371: =VLOOKUP(C371,'Code ONU'!$C$1:$E$231,3,FALSE) -> Europe occidentale | C371: GRC | D371: 2018 | E371: 10740 | F371: 774 | G371: 0.072067039
A372: Guadeloupe | B372: =VLOOKUP(C372,'Code ONU'!$C$1:$E$231,3,FALSE) -> Caraïbes | C372: GLP | D372: 2018 | E372: 418 | F372: 351 | G372: 0.83971292
A373: Guinée | B373: =VLOOKUP(C373,'Code ONU'!$C$1:$E$231,3,FALSE) -> Afrique de l'Ouest | C373: GIN | D373: 2018 | E373: 12543 | F373: 3189 | G373: 0.2542454
A374: Guinée équatoriale | B374: =VLOOKUP(C374,'Code ONU'!$C$1:$E$231,3,FALSE) -> Afrique centrale | C374: GNQ | D374: 2018 | E374: 1589 | F374: 460 | G374: 0.28949025
A375: Guinée-Bissau | B375: =VLOOKUP(C375,'Code ONU'!$C$1:$E$231,3,FALSE) -> Afrique de l'Ouest | C375: GNB | D375: 2018 | E375: 1900 | F375: 292 | G375: 0.15368421
A376: Guyane française | B376: =VLOOKUP(C376,'Code ONU'!$C$1:$E$231,3,FALSE) -> Amériques | C376: GUF | D376: 2018 | E376: 279 | F376: 173 | G376: 0.62007168
A377: Haïti | B377: =VLOOKUP(C377,'Code ONU'!$C$1:$E$231,3,FALSE) -> Caraïbes | C377: HTI | D377: 2018 | E377: 10891 | F377: 4574 | G377: 0.4199798
A378: Hongrie | B378: =VLOOKUP(C378,'Code ONU'!$C$1:$E$231,3,FALSE) -> Europe centrale et orientale | C378: HUN | D378: 2018 | E378: 9777 | F378: 115 | G378: 0.011762299
A379: Îles Wallis-et-Futuna | B379: =VLOOKUP(C379,'Code ONU'!$C$1:$E$231,3,FALSE) -> Océanie | C379: WLF | D379: 2018 | E379: 12 | F379: 10 | G379: 0.83333333
...
